Traceback (most recent call last):
  File "/home/khanh/miniconda3/envs/deepai-book/lib/python3.9/site-packages/jupyter_cache/executors/utils.py", line 51, in single_nb_execution
    executenb(
  File "/home/khanh/miniconda3/envs/deepai-book/lib/python3.9/site-packages/nbclient/client.py", line 1093, in execute
    return NotebookClient(nb=nb, resources=resources, km=km, **kwargs).execute()
  File "/home/khanh/miniconda3/envs/deepai-book/lib/python3.9/site-packages/nbclient/util.py", line 84, in wrapped
    return just_run(coro(*args, **kwargs))
  File "/home/khanh/miniconda3/envs/deepai-book/lib/python3.9/site-packages/nbclient/util.py", line 62, in just_run
    return loop.run_until_complete(coro)
  File "/home/khanh/miniconda3/envs/deepai-book/lib/python3.9/asyncio/base_events.py", line 642, in run_until_complete
    return future.result()
  File "/home/khanh/miniconda3/envs/deepai-book/lib/python3.9/site-packages/nbclient/client.py", line 559, in async_execute
    await self.async_execute_cell(
  File "/home/khanh/miniconda3/envs/deepai-book/lib/python3.9/site-packages/nbclient/client.py", line 854, in async_execute_cell
    self._check_raise_for_error(cell, exec_reply)
  File "/home/khanh/miniconda3/envs/deepai-book/lib/python3.9/site-packages/nbclient/client.py", line 756, in _check_raise_for_error
    raise CellExecutionError.from_cell_and_msg(cell, exec_reply_content)
nbclient.exceptions.CellExecutionError: An error occurred while executing the following cell:
------------------
import graphviz
from sklearn import tree

dot_data = tree.export_graphviz(tree_clf, out_file=None, 
                                feature_names=boston.feature_names,  
                                class_names=['low', 'high'],
                                rounded=True,
                                filled=True)

graph = graphviz.Source(dot_data, format="png")
graph
------------------

[0;31m---------------------------------------------------------------------------[0m
[0;31mModuleNotFoundError[0m                       Traceback (most recent call last)
[0;32m/tmp/ipykernel_19638/2901286609.py[0m in [0;36m<module>[0;34m[0m
[0;32m----> 1[0;31m [0;32mimport[0m [0mgraphviz[0m[0;34m[0m[0;34m[0m[0m
[0m[1;32m      2[0m [0;32mfrom[0m [0msklearn[0m [0;32mimport[0m [0mtree[0m[0;34m[0m[0;34m[0m[0m
[1;32m      3[0m [0;34m[0m[0m
[1;32m      4[0m dot_data = tree.export_graphviz(tree_clf, out_file=None, 
[1;32m      5[0m                                 [0mfeature_names[0m[0;34m=[0m[0mboston[0m[0;34m.[0m[0mfeature_names[0m[0;34m,[0m[0;34m[0m[0;34m[0m[0m

[0;31mModuleNotFoundError[0m: No module named 'graphviz'
ModuleNotFoundError: No module named 'graphviz'

